<?xml version="1.0" encoding="utf-8"?>
<!-- =================================================================================== -->
<!-- |    This document was autogenerated by xacro from minion.urdf.xacro              | -->
<!-- |    EDITING THIS FILE BY HAND IS NOT RECOMMENDED                                 | -->
<!-- =================================================================================== -->
<robot name="minion" xmlns:xacro="http://www.ros.org/wiki/xacro">
  <!-- Init colour -->
  <material name="black">
    <color rgba="0.0 0.0 0.0 1.0"/>
  </material>
  <material name="dark">
    <color rgba="0.3 0.3 0.3 1.0"/>
  </material>
  <material name="light_black">
    <color rgba="0.4 0.4 0.4 1.0"/>
  </material>
  <material name="blue">
    <color rgba="0.0 0.0 0.8 1.0"/>
  </material>
  <material name="green">
    <color rgba="0.0 0.8 0.0 1.0"/>
  </material>
  <material name="grey">
    <color rgba="0.5 0.5 0.5 1.0"/>
  </material>
  <material name="orange">
    <color rgba="1.0 0.423529411765 0.0392156862745 1.0"/>
  </material>
  <material name="brown">
    <color rgba="0.870588235294 0.811764705882 0.764705882353 1.0"/>
  </material>
  <material name="red">
    <color rgba="0.8 0.0 0.0 1.0"/>
  </material>
  <material name="white">
    <color rgba="1.0 1.0 1.0 1.0"/>
  </material>
  <!--Base Footprint-->
  <link name="base_footprint">
    <inertial>
      <mass value="10"/>
      <inertia ixx="1.66666666667e-06" ixy="0.0" ixz="0.0" iyy="1.66666666667e-06" iyz="0.0" izz="1.66666666667e-06"/>
    </inertial>
    <visual>
      <origin rpy="0 0 0" xyz="0 0 0"/>
      <geometry>
        <box size="0.001 0.001 0.001"/>
      </geometry>
    </visual>
  </link>
  <!--Base link-->
  <link name="base_link">
    <inertial>
      <mass value="1"/>
      <inertia ixx="0.001983" ixy="0.0" ixz="0.0" iyy="0.00729375" iyz="0.0" izz="0.00552675"/>
    </inertial>
    <visual>
      <geometry>
        <box size="0.255 0.15 0.036"/>
      </geometry>
      <material name="orange"/>
    </visual>
    <collision>
      <geometry>
        <box size="0.255 0.15 0.036"/>
      </geometry>
    </collision>
  </link>
  <!--base_link to base_footprint Joint-->
  <joint name="base_link_joint" type="fixed">
    <origin rpy="0 0 0" xyz="0 0 0.01"/>
    <parent link="base_footprint"/>
    <child link="base_link"/>
  </joint>
  <link name="left_f_wheel">
    <visual>
      <origin rpy="1.57079632679 0 0" xyz="0 0 0"/>
      <geometry>
        <cylinder length="0.027" radius="0.032"/>
      </geometry>
      <material name="light_black"/>
    </visual>
    <collision>
      <origin rpy="1.57079632679 0 0" xyz="0 0 0"/>
      <geometry>
        <cylinder length="0.027" radius="0.032"/>
      </geometry>
    </collision>
    <inertial>
      <mass value="1"/>
      <inertia ixx="0.00031675" ixy="0" ixz="0" iyy="0.00031675" iyz="0" izz="0.000512"/>
    </inertial>
  </link>
  <joint name="left_f_wheel_joint" type="continuous">
    <axis rpy="0 0 0" xyz="0 1 0"/>
    <parent link="base_link"/>
    <child link="left_f_wheel"/>
    <origin rpy="0 0 0" xyz="0.057 0.077 0}"/>
  </joint>
  <link name="right_f_wheel">
    <visual>
      <origin rpy="1.57079632679 0 0" xyz="0 0 0"/>
      <geometry>
        <cylinder length="0.027" radius="0.032"/>
      </geometry>
      <material name="light_black"/>
    </visual>
    <collision>
      <origin rpy="1.57079632679 0 0" xyz="0 0 0"/>
      <geometry>
        <cylinder length="0.027" radius="0.032"/>
      </geometry>
    </collision>
    <inertial>
      <mass value="1"/>
      <inertia ixx="0.00031675" ixy="0" ixz="0" iyy="0.00031675" iyz="0" izz="0.000512"/>
    </inertial>
  </link>
  <joint name="right_f_wheel_joint" type="continuous">
    <axis rpy="0 0 0" xyz="0 1 0"/>
    <parent link="base_link"/>
    <child link="right_f_wheel"/>
    <origin rpy="0 0 0" xyz="0.057 -0.077 0}"/>
  </joint>
  <link name="left_b_wheel">
    <visual>
      <origin rpy="1.57079632679 0 0" xyz="0 0 0"/>
      <geometry>
        <cylinder length="0.027" radius="0.032"/>
      </geometry>
      <material name="grey"/>
    </visual>
    <collision>
      <origin rpy="1.57079632679 0 0" xyz="0 0 0"/>
      <geometry>
        <cylinder length="0.027" radius="0.032"/>
      </geometry>
    </collision>
    <inertial>
      <mass value="1"/>
      <inertia ixx="0.00031675" ixy="0" ixz="0" iyy="0.00031675" iyz="0" izz="0.000512"/>
    </inertial>
  </link>
  <joint name="left_b_wheel_joint" type="continuous">
    <axis rpy="0 0 0" xyz="0 1 0"/>
    <parent link="base_link"/>
    <child link="left_b_wheel"/>
    <origin rpy="0 0 0" xyz="-0.057 0.077 0}"/>
  </joint>
  <link name="right_b_wheel">
    <visual>
      <origin rpy="1.57079632679 0 0" xyz="0 0 0"/>
      <geometry>
        <cylinder length="0.027" radius="0.032"/>
      </geometry>
      <material name="grey"/>
    </visual>
    <collision>
      <origin rpy="1.57079632679 0 0" xyz="0 0 0"/>
      <geometry>
        <cylinder length="0.027" radius="0.032"/>
      </geometry>
    </collision>
    <inertial>
      <mass value="1"/>
      <inertia ixx="0.00031675" ixy="0" ixz="0" iyy="0.00031675" iyz="0" izz="0.000512"/>
    </inertial>
  </link>
  <joint name="right_b_wheel_joint" type="continuous">
    <axis rpy="0 0 0" xyz="0 1 0"/>
    <parent link="base_link"/>
    <child link="right_b_wheel"/>
    <origin rpy="0 0 0" xyz="-0.057 -0.077 0}"/>
  </joint>
</robot>
